Workbook

Sheet Weekly Waste
A1: Week | B1: Phase | C1: Food Waste (kg)
A2: B1 | B2: Baseline | C2: 486 | E2: Baseline Avg (B1–B4) | F2: =AVERAGE(C2:C5) -> 488.5
A3: B2 | B3: Baseline | C3: 501 | E3: Final 4-Wk Avg (A5–A8) | F3: =AVERAGE(C10:C13) -> 304
A4: B3 | B4: Baseline | C4: 472 | E4: Change | F4: =F3/F2-1 -> -0.3776868
A5: B4 | B5: Baseline | C5: 495
A6: A1 | B6: Agent | C6: 443
A7: A2 | B7: Agent | C7: 409
A8: A3 | B8: Agent | C8: 381
A9: A4 | B9: Agent | C9: 352
A10: A5 | B10: Agent | C10: 329
A11: A6 | B11: Agent | C11: 310
A12: A7 | B12: Agent | C12: 296
A13: A8 | B13: Agent | C13: 281

Sheet Waste by Source
A1: Waste Source | B1: Baseline (kg/wk) | C1: With Agents (kg/wk) | D1: Change
A2: Overproduction | B2: 215 | C2: 103 | D2: =C2/B2-1 -> -0.52093023 | F2: Baseline = B1–B4 average; With Agents = A5–A8 average.
A3: Buffet Excess | B3: 108 | C3: 76 | D3: =C3/B3-1 -> -0.2962963
A4: Spoilage | B4: 92 | C4: 56 | D4: =C4/B4-1 -> -0.39130435
A5: Prep Waste | B5: 44 | C5: 39 | D5: =C5/B5-1 -> -0.11363636
A6: Plate Waste | B6: 30 | C6: 30 | D6: =C6/B6-1 -> 0
A7: Total | B7: =SUM(B2:B6) -> 489 | C7: =SUM(C2:C6) -> 304 | D7: =C7/B7-1 -> -0.37832311

Sheet Forecast MAPE
A1: Week | B1: Phase | C1: Forecast MAPE
A2: B1 | B2: Baseline | C2: 0.182 | E2: Baseline Avg (B1–B4) | F2: =AVERAGE(C2:C5) -> 0.17775
A3: B2 | B3: Baseline | C3: 0.171 | E3: Final Week (A8) | F3: =C13 -> 0.072
A4: B3 | B4: Baseline | C4: 0.19 | E4: Change | F4: =F3/F2-1 -> -0.59493671
A5: B4 | B5: Baseline | C5: 0.168 | E5: MAPE = mean(|Actual - Forecast| / Actual) x 100, across the week's services.
A6: A1 | B6: Agent | C6: 0.149
A7: A2 | B7: Agent | C7: 0.132
A8: A3 | B8: Agent | C8: 0.117
A9: A4 | B9: Agent | C9: 0.104
A10: A5 | B10: Agent | C10: 0.092
A11: A6 | B11: Agent | C11: 0.085
A12: A7 | B12: Agent | C12: 0.078
A13: A8 | B13: Agent | C13: 0.072

Sheet Waste Cost
A1: Step | B1: Amount ($) | C1: Chart Base | D1: Chart Bar | F1: Inputs
A2: Baseline Waste Cost | B2: =G3 -> 384000 | C2: 0 | D2: =B2 -> 384000 | F2: Annual Food Purchasing | G2: 3200000
A3: Overproduction | B3: -86000 | C3: =C2+D2+B3 -> 298000 | D3: =-B3 -> 86000 | F3: Baseline Annual Waste Cost | G3: 384000
A4: Spoilage | B4: -29000 | C4: =C3+B4 -> 269000 | D4: =-B4 -> 29000 | F4: Waste Cost % of Purchasing | G4: =G3/G2 -> 0.12
A5: Buffet Excess | B5: -26000 | C5: =C4+B5 -> 243000 | D5: =-B5 -> 26000
A6: Other Efficiency | B6: -4000 | C6: =C5+B6 -> 239000 | D6: =-B6 -> 4000
A7: Optimized Waste Cost | B7: =SUM(B2:B6) -> 239000 | C7: 0 | D7: =B7 -> 239000
A9: Annual Food Cost Protected | B9: =B2-B7 -> 145000
A10: Reduction in Waste Cost | B10: =B9/B2 -> 0.37760417
A11: Avoided waste cost, not incremental revenue.

Sheet Guest Experience
A1: Week | B1: Phase | C1: Waste / Cover (kg) | D1: Guest F&B Score
A2: B1 | B2: Baseline | C2: 0.164 | D2: 4.61
A3: B2 | B3: Baseline | C3: 0.168 | D3: 4.6
A4: B3 | B4: Baseline | C4: 0.158 | D4: 4.63
A5: B4 | B5: Baseline | C5: 0.165 | D5: 4.62
A6: A1 | B6: Agent | C6: 0.148 | D6: 4.62
A7: A2 | B7: Agent | C7: 0.137 | D7: 4.64
A8: A3 | B8: Agent | C8: 0.127 | D8: 4.63
A9: A4 | B9: Agent | C9: 0.117 | D9: 4.65
A10: A5 | B10: Agent | C10: 0.11 | D10: 4.66
A11: A6 | B11: Agent | C11: 0.104 | D11: 4.65
A12: A7 | B12: Agent | C12: 0.099 | D12: 4.67
A13: A8 | B13: Agent | C13: 0.094 | D13: 4.68
A15: Waste / Cover: Baseline Avg | D15: =AVERAGE(C2:C5) -> 0.16375
A16: Waste / Cover: Week A8 | D16: =C13 -> 0.094
A17: Waste / Cover Change | D17: =D16/D15-1 -> -0.4259542
A18: Guest Score: B1 | D18: =D2 -> 4.61
A19: Guest Score: A8 | D19: =D13 -> 4.68

Sheet Operations
A1: Week | B1: Coordination Hours / Week
A2: Baseline | B2: 18.5
A3: A1 | B3: 17
A4: A2 | B4: 15.5
A5: A3 | B5: 14.2
A6: A4 | B6: 13.1
A7: A5 | B7: 12
A8: A6 | B8: 11.4
A9: A7 | B9: 10.8
A10: A8 | B10: 10.3
A12: Baseline | B12: =B2 -> 18.5
A13: Week A8 | B13: =B10 -> 10.3
A14: Change | B14: =B13/B12-1 -> -0.44324324

Sheet AgentOps
A1: Week | B1: Recommendations | C1: Accepted | D1: Human Overrides | E1: Required Escalations | F1: Correct Escalations | G1: All Escalations | H1: Tool Calls | I1: Successful Tool Calls | J1: Acceptance Rate | K1: Override Rate | L1: Escalation Recall | M1: Escalation Precision | N1: Tool Reliability | O1: Autonomy Score
A2: A1 | B2: 100 | C2: 61 | D2: 29 | E2: 27 | F2: 20 | G2: 27 | H2: 520 | I2: 503 | J2: =C2/B2 -> 0.61 | K2: =D2/B2 -> 0.29 | L2: =F2/E2 -> 0.74074074 | M2: =F2/G2 -> 0.74074074 | N2: =I2/H2 -> 0.96730769 | O2: =J2*30+L2*25+M2*20+N2*15+(1-K2)*10 -> 73.242949
A3: A2 | B3: 108 | C3: 72 | D3: 27 | E3: 27 | F3: 21 | G3: 27 | H3: 545 | I3: 531 | J3: =C3/B3 -> 0.66666667 | K3: =D3/B3 -> 0.25 | L3: =F3/E3 -> 0.77777778 | M3: =F3/G3 -> 0.77777778 | N3: =I3/H3 -> 0.97431193 | O3: =J3*30+L3*25+M3*20+N3*15+(1-K3)*10 -> 77.114679
A4: A3 | B4: 115 | C4: 83 | D4: 24 | E4: 28 | F4: 23 | G4: 28 | H4: 570 | I4: 559 | J4: =C4/B4 -> 0.72173913 | K4: =D4/B4 -> 0.20869565 | L4: =F4/E4 -> 0.82142857 | M4: =F4/G4 -> 0.82142857 | N4: =I4/H4 -> 0.98070175 | O4: =J4*30+L4*25+M4*20+N4*15+(1-K4)*10 -> 81.240029
A5: A4 | B5: 121 | C5: 92 | D5: 22 | E5: 27 | F5: 23 | G5: 27 | H5: 595 | I5: 586 | J5: =C5/B5 -> 0.76033058 | K5: =D5/B5 -> 0.18181818 | L5: =F5/E5 -> 0.85185185 | M5: =F5/G5 -> 0.85185185 | N5: =I5/H5 -> 0.98487395 | O5: =J5*30+L5*25+M5*20+N5*15+(1-K5)*10 -> 84.098178
A6: A5 | B6: 128 | C6: 102 | D6: 19 | E6: 26 | F6: 23 | G6: 27 | H6: 620 | I6: 612 | J6: =C6/B6 -> 0.796875 | K6: =D6/B6 -> 0.1484375 | L6: =F6/E6 -> 0.88461538 | M6: =F6/G6 -> 0.85185185 | N6: =I6/H6 -> 0.98709677 | O6: =J6*30+L6*25+M6*20+N6*15+(1-K6)*10 -> 86.380748
A7: A6 | B7: 132 | C7: 110 | D7: 17 | E7: 25 | F7: 23 | G7: 26 | H7: 640 | I7: 633 | J7: =C7/B7 -> 0.83333333 | K7: =D7/B7 -> 0.12878788 | L7: =F7/E7 -> 0.92 | M7: =F7/G7 -> 0.88461538 | N7: =I7/H7 -> 0.9890625 | O7: =J7*30+L7*25+M7*20+N7*15+(1-K7)*10 -> 89.240366
A8: A7 | B8: 139 | C8: 120 | D8: 15 | E8: 27 | F8: 25 | G8: 27 | H8: 665 | I8: 659 | J8: =C8/B8 -> 0.86330935 | K8: =D8/B8 -> 0.10791367 | L8: =F8/E8 -> 0.92592593 | M8: =F8/G8 -> 0.92592593 | N8: =I8/H8 -> 0.99097744 | O8: =J8*30+L8*25+M8*20+N8*15+(1-K8)*10 -> 91.351472
A9: A8 | B9: 145 | C9: 128 | D9: 13 | E9: 22 | F9: 21 | G9: 23 | H9: 690 | I9: 686 | J9: =C9/B9 -> 0.88275862 | K9: =D9/B9 -> 0.089655172 | L9: =F9/E9 -> 0.95454545 | M9: =F9/G9 -> 0.91304348 | N9: =I9/H9 -> 0.9942029 | O9: =J9*30+L9*25+M9*20+N9*15+(1-K9)*10 -> 92.623756
A11: Source: Hotel_Food_Waste_AgentOps_Metrics.xlsx (Amelia Wolfire) — values and formulas reproduced unchanged.

Sheet Readiness Gate
A1: Readiness Criterion | B1: Test | C1: Threshold
A2: Recommendation Acceptance | B2: ≥ | C2: 0.8 | D2: Illustrative thresholds — edit the blue cells.
A3: Escalation Recall | B3: ≥ | C3: 0.9
A4: Escalation Precision | B4: ≥ | C4: 0.85
A5: Tool Reliability | B5: ≥ | C5: 0.99
A6: Human Override Rate | B6: ≤ | C6: 0.15
A7: Forecast MAPE | B7: ≤ | C7: 0.1
A8: Guest F&B Score | B8: ≥ | C8: 4.6
A9: Critical Policy Violations | B9: = | C9: 0
A11: Week | B11: Acceptance | C11: Recall | D11: Precision | E11: Tool Reliability | F11: Override Rate | G11: MAPE | H11: Guest Score | I11: Policy Violations | J11: Failed Checks | K11: Gate | L11: First Blocker | M11: Autonomy Score
A12: A1 | B12: =AgentOps!J2 -> 0.61 | C12: =AgentOps!L2 -> 0.74074074 | D12: =AgentOps!M2 -> 0.74074074 | E12: =AgentOps!N2 -> 0.96730769 | F12: =AgentOps!K2 -> 0.29 | G12: ='Forecast MAPE'!C6 -> 0.149 | H12: ='Guest Experience'!D6 -> 4.62 | I12: 0 | J12: =(B12<$C$2)+(C12<$C$3)+(D12<$C$4)+(E12<$C$5)+(F12>$C$6)+(G12>$C$7)+(H12<$C$8)+(I12<>$C$9) -> 6 | K12: =IF(AND(B12>=$C$2,C12>=$C$3,D12>=$C$4,E12>=$C$5,F12<=$C$6,G12<=$C$7,H12>=$C$8,I12=$C$9),"PASS","HOLD") -> HOLD | L12: =IF(K12="PASS","—",IF(B12<$C$2,"Acceptance",IF(C12<$C$3,"Recall",IF(D12<$C$4,"Precision",IF(E12<$C$5,"Tool reliability",IF(F12>$C$6,"Override rate",IF(G12>$C$7,"MAPE",IF(H12<$C$8,"Guest score","Policy")))))))) -> Acceptance | M12: =AgentOps!O2 -> 73.242949
A13: A2 | B13: =AgentOps!J3 -> 0.66666667 | C13: =AgentOps!L3 -> 0.77777778 | D13: =AgentOps!M3 -> 0.77777778 | E13: =AgentOps!N3 -> 0.97431193 | F13: =AgentOps!K3 -> 0.25 | G13: ='Forecast MAPE'!C7 -> 0.132 | H13: ='Guest Experience'!D7 -> 4.64 | I13: 0 | J13: =(B13<$C$2)+(C13<$C$3)+(D13<$C$4)+(E13<$C$5)+(F13>$C$6)+(G13>$C$7)+(H13<$C$8)+(I13<>$C$9) -> 6 | K13: =IF(AND(B13>=$C$2,C13>=$C$3,D13>=$C$4,E13>=$C$5,F13<=$C$6,G13<=$C$7,H13>=$C$8,I13=$C$9),"PASS","HOLD") -> HOLD | L13: =IF(K13="PASS","—",IF(B13<$C$2,"Acceptance",IF(C13<$C$3,"Recall",IF(D13<$C$4,"Precision",IF(E13<$C$5,"Tool reliability",IF(F13>$C$6,"Override rate",IF(G13>$C$7,"MAPE",IF(H13<$C$8,"Guest score","Policy")))))))) -> Acceptance | M13: =AgentOps!O3 -> 77.114679
A14: A3 | B14: =AgentOps!J4 -> 0.72173913 | C14: =AgentOps!L4 -> 0.82142857 | D14: =AgentOps!M4 -> 0.82142857 | E14: =AgentOps!N4 -> 0.98070175 | F14: =AgentOps!K4 -> 0.20869565 | G14: ='Forecast MAPE'!C8 -> 0.117 | H14: ='Guest Experience'!D8 -> 4.63 | I14: 0 | J14: =(B14<$C$2)+(C14<$C$3)+(D14<$C$4)+(E14<$C$5)+(F14>$C$6)+(G14>$C$7)+(H14<$C$8)+(I14<>$C$9) -> 6 | K14: =IF(AND(B14>=$C$2,C14>=$C$3,D14>=$C$4,E14>=$C$5,F14<=$C$6,G14<=$C$7,H14>=$C$8,I14=$C$9),"PASS","HOLD") -> HOLD | L14: =IF(K14="PASS","—",IF(B14<$C$2,"Acceptance",IF(C14<$C$3,"Recall",IF(D14<$C$4,"Precision",IF(E14<$C$5,"Tool reliability",IF(F14>$C$6,"Override rate",IF(G14>$C$7,"MAPE",IF(H14<$C$8,"Guest score","Policy")))))))) -> Acceptance | M14: =AgentOps!O4 -> 81.240029
A15: A4 | B15: =AgentOps!J5 -> 0.76033058 | C15: =AgentOps!L5 -> 0.85185185 | D15: =AgentOps!M5 -> 0.85185185 | E15: =AgentOps!N5 -> 0.98487395 | F15: =AgentOps!K5 -> 0.18181818 | G15: ='Forecast MAPE'!C9 -> 0.104 | H15: ='Guest Experience'!D9 -> 4.65 | I15: 0 | J15: =(B15<$C$2)+(C15<$C$3)+(D15<$C$4)+(E15<$C$5)+(F15>$C$6)+(G15>$C$7)+(H15<$C$8)+(I15<>$C$9) -> 5 | K15: =IF(AND(B15>=$C$2,C15>=$C$3,D15>=$C$4,E15>=$C$5,F15<=$C$6,G15<=$C$7,H15>=$C$8,I15=$C$9),"PASS","HOLD") -> HOLD | L15: =IF(K15="PASS","—",IF(B15<$C$2,"Acceptance",IF(C15<$C$3,"Recall",IF(D15<$C$4,"Precision",IF(E15<$C$5,"Tool reliability",IF(F15>$C$6,"Override rate",IF(G15>$C$7,"MAPE",IF(H15<$C$8,"Guest score","Policy")))))))) -> Acceptance | M15: =AgentOps!O5 -> 84.098178
A16: A5 | B16: =AgentOps!J6 -> 0.796875 | C16: =AgentOps!L6 -> 0.88461538 | D16: =AgentOps!M6 -> 0.85185185 | E16: =AgentOps!N6 -> 0.98709677 | F16: =AgentOps!K6 -> 0.1484375 | G16: ='Forecast MAPE'!C10 -> 0.092 | H16: ='Guest Experience'!D10 -> 4.66 | I16: 0 | J16: =(B16<$C$2)+(C16<$C$3)+(D16<$C$4)+(E16<$C$5)+(F16>$C$6)+(G16>$C$7)+(H16<$C$8)+(I16<>$C$9) -> 3 | K16: =IF(AND(B16>=$C$2,C16>=$C$3,D16>=$C$4,E16>=$C$5,F16<=$C$6,G16<=$C$7,H16>=$C$8,I16=$C$9),"PASS","HOLD") -> HOLD | L16: =IF(K16="PASS","—",IF(B16<$C$2,"Acceptance",IF(C16<$C$3,"Recall",IF(D16<$C$4,"Precision",IF(E16<$C$5,"Tool reliability",IF(F16>$C$6,"Override rate",IF(G16>$C$7,"MAPE",IF(H16<$C$8,"Guest score","Policy")))))))) -> Acceptance | M16: =AgentOps!O6 -> 86.380748
A17: A6 | B17: =AgentOps!J7 -> 0.83333333 | C17: =AgentOps!L7 -> 0.92 | D17: =AgentOps!M7 -> 0.88461538 | E17: =AgentOps!N7 -> 0.9890625 | F17: =AgentOps!K7 -> 0.12878788 | G17: ='Forecast MAPE'!C11 -> 0.085 | H17: ='Guest Experience'!D11 -> 4.65 | I17: 0 | J17: =(B17<$C$2)+(C17<$C$3)+(D17<$C$4)+(E17<$C$5)+(F17>$C$6)+(G17>$C$7)+(H17<$C$8)+(I17<>$C$9) -> 1 | K17: =IF(AND(B17>=$C$2,C17>=$C$3,D17>=$C$4,E17>=$C$5,F17<=$C$6,G17<=$C$7,H17>=$C$8,I17=$C$9),"PASS","HOLD") -> HOLD | L17: =IF(K17="PASS","—",IF(B17<$C$2,"Acceptance",IF(C17<$C$3,"Recall",IF(D17<$C$4,"Precision",IF(E17<$C$5,"Tool reliability",IF(F17>$C$6,"Override rate",IF(G17>$C$7,"MAPE",IF(H17<$C$8,"Guest score","Policy")))))))) -> Tool reliability | M17: =AgentOps!O7 -> 89.240366
A18: A7 | B18: =AgentOps!J8 -> 0.86330935 | C18: =AgentOps!L8 -> 0.92592593 | D18: =AgentOps!M8 -> 0.92592593 | E18: =AgentOps!N8 -> 0.99097744 | F18: =AgentOps!K8 -> 0.10791367 | G18: ='Forecast MAPE'!C12 -> 0.078 | H18: ='Guest Experience'!D12 -> 4.67 | I18: 0 | J18: =(B18<$C$2)+(C18<$C$3)+(D18<$C$4)+(E18<$C$5)+(F18>$C$6)+(G18>$C$7)+(H18<$C$8)+(I18<>$C$9) -> 0 | K18: =IF(AND(B18>=$C$2,C18>=$C$3,D18>=$C$4,E18>=$C$5,F18<=$C$6,G18<=$C$7,H18>=$C$8,I18=$C$9),"PASS","HOLD") -> PASS | L18: =IF(K18="PASS","—",IF(B18<$C$2,"Acceptance",IF(C18<$C$3,"Recall",IF(D18<$C$4,"Precision",IF(E18<$C$5,"Tool reliability",IF(F18>$C$6,"Override rate",IF(G18>$C$7,"MAPE",IF(H18<$C$8,"Guest score","Policy")))))))) -> — | M18: =AgentOps!O8 -> 91.351472
A19: A8 | B19: =AgentOps!J9 -> 0.88275862 | C19: =AgentOps!L9 -> 0.95454545 | D19: =AgentOps!M9 -> 0.91304348 | E19: =AgentOps!N9 -> 0.9942029 | F19: =AgentOps!K9 -> 0.089655172 | G19: ='Forecast MAPE'!C13 -> 0.072 | H19: ='Guest Experience'!D13 -> 4.68 | I19: 0 | J19: =(B19<$C$2)+(C19<$C$3)+(D19<$C$4)+(E19<$C$5)+(F19>$C$6)+(G19>$C$7)+(H19<$C$8)+(I19<>$C$9) -> 0 | K19: =IF(AND(B19>=$C$2,C19>=$C$3,D19>=$C$4,E19>=$C$5,F19<=$C$6,G19<=$C$7,H19>=$C$8,I19=$C$9),"PASS","HOLD") -> PASS | L19: =IF(K19="PASS","—",IF(B19<$C$2,"Acceptance",IF(C19<$C$3,"Recall",IF(D19<$C$4,"Precision",IF(E19<$C$5,"Tool reliability",IF(F19>$C$6,"Override rate",IF(G19>$C$7,"MAPE",IF(H19<$C$8,"Guest score","Policy")))))))) -> — | M19: =AgentOps!O9 -> 92.623756
A20: Policy violations: modeled at 0 for every agent week (illustrative).
A22: Autonomy Score construction
A23: Recommendation Acceptance | C23: 0.3
A24: Escalation Recall | C24: 0.25
A25: Escalation Precision | C25: 0.2
A26: Tool Reliability | C26: 0.15
A27: Inverse Override Rate (1 − override) | C27: 0.1
A28: Weight total | C28: =SUM(C23:C27) -> 1
A29: Case-study composite index; illustrative weighting. A high score informs, but never by itself grants, more authority.

Sheet Control Room
A1: Category | B1: KPI (week A8) | C1: Value | D1: Test | E1: Target | F1: Status | G1: Source
A2: QUALITY | B2: Recommendation Acceptance | C2: =AgentOps!J9 -> 0.88275862 | D2: >= | E2: 0.8 | F2: =IF(D2=">=",IF(C2>=E2,"On target","Watch"),IF(D2="<=",IF(C2<=E2,"On target","Watch"),IF(C2=E2,"On target","Watch"))) -> On target | G2: AgentOps
A3: QUALITY | B3: Forecast MAPE | C3: ='Forecast MAPE'!C13 -> 0.072 | D3: <= | E3: 0.1 | F3: =IF(D3=">=",IF(C3>=E3,"On target","Watch"),IF(D3="<=",IF(C3<=E3,"On target","Watch"),IF(C3=E3,"On target","Watch"))) -> On target | G3: Forecast MAPE
A4: QUALITY | B4: Recommendation Outcome Quality | C4: 0.91 | D4: >= | E4: 0.85 | F4: =IF(D4=">=",IF(C4>=E4,"On target","Watch"),IF(D4="<=",IF(C4<=E4,"On target","Watch"),IF(C4=E4,"On target","Watch"))) -> On target | G4: Modeled
A5: SAFETY | B5: Escalation Recall | C5: =AgentOps!L9 -> 0.95454545 | D5: >= | E5: 0.9 | F5: =IF(D5=">=",IF(C5>=E5,"On target","Watch"),IF(D5="<=",IF(C5<=E5,"On target","Watch"),IF(C5=E5,"On target","Watch"))) -> On target | G5: AgentOps
A6: SAFETY | B6: Escalation Precision | C6: =AgentOps!M9 -> 0.91304348 | D6: >= | E6: 0.85 | F6: =IF(D6=">=",IF(C6>=E6,"On target","Watch"),IF(D6="<=",IF(C6<=E6,"On target","Watch"),IF(C6=E6,"On target","Watch"))) -> On target | G6: AgentOps
A7: SAFETY | B7: Policy Violations | C7: 0 | D7: = | E7: 0 | F7: =IF(D7=">=",IF(C7>=E7,"On target","Watch"),IF(D7="<=",IF(C7<=E7,"On target","Watch"),IF(C7=E7,"On target","Watch"))) -> On target | G7: Modeled
A8: SAFETY | B8: Correct Abstention Rate | C8: 0.92 | D8: >= | E8: 0.9 | F8: =IF(D8=">=",IF(C8>=E8,"On target","Watch"),IF(D8="<=",IF(C8<=E8,"On target","Watch"),IF(C8=E8,"On target","Watch"))) -> On target | G8: Modeled
A9: RELIABILITY | B9: Tool / API Reliability | C9: =AgentOps!N9 -> 0.9942029 | D9: >= | E9: 0.99 | F9: =IF(D9=">=",IF(C9>=E9,"On target","Watch"),IF(D9="<=",IF(C9<=E9,"On target","Watch"),IF(C9=E9,"On target","Watch"))) -> On target | G9: AgentOps
A10: RELIABILITY | B10: Context Completeness | C10: 0.978 | D10: >= | E10: 0.95 | F10: =IF(D10=">=",IF(C10>=E10,"On target","Watch"),IF(D10="<=",IF(C10<=E10,"On target","Watch"),IF(C10=E10,"On target","Watch"))) -> On target | G10: Modeled
A11: RELIABILITY | B11: Human Override Rate | C11: =AgentOps!K9 -> 0.089655172 | D11: <= | E11: 0.15 | F11: =IF(D11=">=",IF(C11>=E11,"On target","Watch"),IF(D11="<=",IF(C11<=E11,"On target","Watch"),IF(C11=E11,"On target","Watch"))) -> On target | G11: AgentOps
A12: RELIABILITY | B12: Execution Failure Rate | C12: 0.006 | D12: <= | E12: 0.01 | F12: =IF(D12=">=",IF(C12>=E12,"On target","Watch"),IF(D12="<=",IF(C12<=E12,"On target","Watch"),IF(C12=E12,"On target","Watch"))) -> On target | G12: Modeled
A13: BUSINESS | B13: Food Waste Reduction | C13: =-'Weekly Waste'!F4 -> 0.3776868 | F13: Outcome | G13: Weekly Waste
A14: BUSINESS | B14: Waste Cost Avoided (annual) | C14: ='Waste Cost'!B9 -> 145000 | F14: Outcome | G14: Waste Cost
A15: BUSINESS | B15: Manager Hours Saved / Week | C15: =Operations!B12-Operations!B13 -> 8.2 | F15: Outcome | G15: Operations
A16: BUSINESS | B16: Guest F&B Score | C16: ='Guest Experience'!D13 -> 4.68 | D16: >= | E16: 4.6 | F16: =IF(D16=">=",IF(C16>=E16,"On target","Watch"),IF(D16="<=",IF(C16<=E16,"On target","Watch"),IF(C16=E16,"On target","Watch"))) -> On target | G16: Guest Experience
A18: Blue values marked 'Modeled' are illustrative assumptions for the case study, not pilot measurements.

Sheet Overrides
A1: Override Reason | B1: Overrides (A1–A8) | C1: Share | D1: System Improvement
A2: Missing context | B2: 38 | C2: =B2/$B$9 -> 0.22891566 | D2: Add banquet and group-block feed to context layer
A3: Special event | B3: 31 | C3: =B3/$B$9 -> 0.18674699 | D3: Integrate events calendar; lower autonomy on event days
A4: Forecast disagreement | B4: 29 | C4: =B4/$B$9 -> 0.1746988 | D4: Retrain demand model on chef-adjusted actuals
A5: Guest-experience concern | B5: 24 | C5: =B5/$B$9 -> 0.14457831 | D5: Add minimum-display guardrail for signature items
A6: Inventory constraint | B6: 19 | C6: =B6/$B$9 -> 0.11445783 | D6: Refresh inventory feed hourly; block on stale data
A7: Policy requirement | B7: 14 | C7: =B7/$B$9 -> 0.084337349 | D7: Encode the policy as a hard constraint
A8: Agent error | B8: 11 | C8: =B8/$B$9 -> 0.06626506 | D8: Log as defect; add a regression case to the evaluation suite
A9: Total | B9: =SUM(B2:B8) -> 166
A10: Check vs AgentOps overrides | B10: =SUM(AgentOps!D2:D9) -> 166 | C10: =IF(B9=B10,"Reconciles","Mismatch") -> Reconciles
A11: Reason split is a modeled diagnostic tagging of the 166 pilot overrides (illustrative).
A13: Drift Scenario (illustrative, post-pilot) | B13: Override Rate | C13: Trailing 3-wk Avg | D13: Drift Signal
A14: P1 | B14: 0.09
A15: P2 | B15: 0.1
A16: P3 | B16: 0.11
A17: P4 | B17: 0.23 | C17: =AVERAGE(B14:B16) -> 0.1 | D17: =IF(B17>1.5*C17,"DRIFT DETECTED","Normal") -> DRIFT DETECTED
A18: Rule: flag drift when the week's override rate exceeds 1.5× its trailing 3-week average.

Sheet Economics
A1: Line Item | B1: Annual ($) | C1: Basis
A2: VALUE
A3: Food cost avoided (incl. spoilage + inventory utilization) | B3: ='Waste Cost'!B9 -> 145000 | C3: Waste Cost sheet
A4: Coordination capacity redeployed | B4: =B20*52*B19 -> 19188 | C4: Hours saved × 52 × loaded rate
A5: Gross annual benefit | B5: =B3+B4 -> 164188
A6: AGENTIC AI OPERATING COST (annual)
A7: Model / API usage | B7: 6000 | C7: Modeled assumption (illustrative) — edit to test.
A8: Monitoring + observability | B8: 6000 | C8: Modeled assumption (illustrative) — edit to test.
A9: Human review of approvals | B9: =B21*52*B19 -> 4680 | C9: Review hours × 52 × loaded rate
A10: Maintenance + evaluation | B10: 12000 | C10: Modeled assumption (illustrative) — edit to test.
A11: Annual AI operating cost | B11: =SUM(B7:B10) -> 28680
A12: ONE-TIME COST
A13: Integration (PMS, POS, inventory, procurement) | B13: 40000 | C13: Modeled assumption (illustrative) — edit to test.
A14: Training + change management | B14: 10000 | C14: Modeled assumption (illustrative) — edit to test.
A15: Total one-time cost | B15: =B13+B14 -> 50000
A17: INPUTS
A19: Manager loaded hourly cost ($) | B19: 45 | C19: Modeled assumption (illustrative) — edit to test.
A20: Manager hours saved / week | B20: =Operations!B12-Operations!B13 -> 8.2
A21: Human review hours / week | B21: 2 | C21: Modeled assumption (illustrative) — edit to test.
A23: RESULTS
A24: Net annual benefit (run-rate) | B24: =B5-B11 -> 135508
A25: Year-1 net benefit | B25: =B24-B15 -> 85508
A26: Year-1 ROI | B26: =B25/(B11+B15) -> 1.0867819
A27: Payback period (months) | B27: =B15/(B24/12) -> 4.4277829
A28: Value / AI operating cost | B28: =B5/B11 -> 5.7248257
A30: Coordination capacity is redeployed manager time, not a cash saving.

Sheet Sensitivity
A1: Scenario Driver | B1: Conservative | C1: Base | D1: Upside
A2: Waste reduction | B2: 0.15 | C2: 0.25 | D2: ='Waste Cost'!B10 -> 0.37760417
A3: Adoption rate | B3: 0.8 | C3: 0.9 | D3: 1
A4: AI operating-cost multiplier | B4: 1.25 | C4: 1 | D4: 1
A5: Food purchasing volume index | B5: 1 | C5: 1 | D5: 1
A7: RESULTS
A8: Food cost avoided | B8: ='Waste Cost'!$G$3*B5*B2*B3 -> 46080 | C8: ='Waste Cost'!$G$3*C5*C2*C3 -> 86400 | D8: ='Waste Cost'!$G$3*D5*D2*D3 -> 145000
A9: Coordination capacity | B9: =Economics!$B$4*B3 -> 15350.4 | C9: =Economics!$B$4*C3 -> 17269.2 | D9: =Economics!$B$4*D3 -> 19188
A10: Gross benefit | B10: =B8+B9 -> 61430.4 | C10: =C8+C9 -> 103669.2 | D10: =D8+D9 -> 164188
A11: AI operating cost | B11: =Economics!$B$11*B4 -> 35850 | C11: =Economics!$B$11*C4 -> 28680 | D11: =Economics!$B$11*D4 -> 28680
A12: Net annual benefit | B12: =B10-B11 -> 25580.4 | C12: =C10-C11 -> 74989.2 | D12: =D10-D11 -> 135508
A13: Payback (months) | B13: =Economics!$B$15/(B12/12) -> 23.455458 | C13: =Economics!$B$15/(C12/12) -> 8.0011522 | D13: =Economics!$B$15/(D12/12) -> 4.4277829
A15: One-way sensitivity (Base net benefit) | B15: Low Case | C15: High Case | D15: Swing
A16: Waste reduction (15% → Upside) | B16: =('Waste Cost'!$G$3*1*$B$2*$C$3+Economics!$B$4*$C$3-Economics!$B$11*1) -> 40429.2 | C16: =('Waste Cost'!$G$3*1*$D$2*$C$3+Economics!$B$4*$C$3-Economics!$B$11*1) -> 119089.2 | D16: =C16-B16 -> 78660
A17: Adoption rate (70% → 100%) | B17: =('Waste Cost'!$G$3*1*$C$2*0.7+Economics!$B$4*0.7-Economics!$B$11*1) -> 51951.6 | C17: =('Waste Cost'!$G$3*1*$C$2*1+Economics!$B$4*1-Economics!$B$11*1) -> 86508 | D17: =C17-B17 -> 34556.4
A18: Food purchasing volume (−20% → +20%) | B18: =('Waste Cost'!$G$3*0.8*$C$2*$C$3+Economics!$B$4*$C$3-Economics!$B$11*1) -> 57709.2 | C18: =('Waste Cost'!$G$3*1.2*$C$2*$C$3+Economics!$B$4*$C$3-Economics!$B$11*1) -> 92269.2 | D18: =C18-B18 -> 34560
A19: AI operating cost (×1.5 → ×0.5) | B19: =('Waste Cost'!$G$3*1*$C$2*$C$3+Economics!$B$4*$C$3-Economics!$B$11*1.5) -> 60649.2 | C19: =('Waste Cost'!$G$3*1*$C$2*$C$3+Economics!$B$4*$C$3-Economics!$B$11*0.5) -> 89329.2 | D19: =C19-B19 -> 28680
A21: Forecast improvement is expressed through the waste-reduction driver. All scenario inputs are modeled assumptions.

Sheet 10_STRATEGY_EXECUTION
A1: 10 · STRATEGY EXECUTION & PERFORMANCE MANAGEMENT
A2: What does leadership actually do with these metrics?
A3: INSIGHT → DECISION → OWNER → ACTION → MEASUREMENT → STRATEGIC OUTCOME
A4: Governance review week | B4: A6 | C4: ◄ Select A1–A8 from the drop-down. Drives Sections A, B and D and the AI-governance row in F. A6 is the week the readiness gate held; switch to A8 for the end-of-pilot review.
A5: All values are calculated in this workbook from modeled case-study data (12-week pilot scenario), not realized hotel performance.
A7: A · STRATEGY MAP
A8: Four strategic objectives in causal order, with AI governance as the enabler beneath them. Each objective's status rolls up automatically from the Section B scorecard: its weakest KPI sets the status.
A9: Level | B9: Strategic Objective | E9: KPIs (Section B) | I9: Status | J9: Leadership Question
A10: OBJECTIVE 1 | B10: Improve Decision Intelligence | E10: Forecast MAPE · Recommendation Acceptance · Context Completeness | I10: =IF(COUNTIF(H23:H25,"OFF TRACK")>0,"OFF TRACK",IF(COUNTIF(H23:H25,"AT RISK")>0,"AT RISK","ON TRACK")) -> ON TRACK | J10: Do we know what demand to expect?
B11: ↓
A12: OBJECTIVE 2 | B12: Improve Operational Efficiency | E12: Overproduction · Waste per Cover · Food Waste · Manager Hours Saved | I12: =IF(COUNTIF(H26:H29,"OFF TRACK")>0,"OFF TRACK",IF(COUNTIF(H26:H29,"AT RISK")>0,"AT RISK","ON TRACK")) -> AT RISK | J12: Are we producing only what guests will use?
B13: ↓
A14: OBJECTIVE 3 | B14: Protect Guest Value | E14: Guest F&B Score · Guest Experience Guardrail · Service-Related Exceptions | I14: =IF(COUNTIF(H30:H32,"OFF TRACK")>0,"OFF TRACK",IF(COUNTIF(H30:H32,"AT RISK")>0,"AT RISK","ON TRACK")) -> ON TRACK | J14: Is the guest experience protected?
B15: ↓
A16: OBJECTIVE 4 | B16: Create Sustainable Business Value | E16: Food Cost Avoided · Net Annual Benefit · ROI · Payback Period | I16: =IF(COUNTIF(H33:H36,"OFF TRACK")>0,"OFF TRACK",IF(COUNTIF(H33:H36,"AT RISK")>0,"AT RISK","ON TRACK")) -> ON TRACK | J16: Is it worth it, net of the AI's own cost?
A17: ENABLER | B17: Earn Greater AI Autonomy | E17: Reliability · Escalation Recall · Override Rate · Readiness Gate | I17: =IF(COUNTIF(H37:H40,"OFF TRACK")>0,"OFF TRACK",IF(COUNTIF(H37:H40,"AT RISK")>0,"AT RISK","ON TRACK")) -> OFF TRACK | J17: Has the agent earned more decision authority?
A18: CAUSAL LOGIC: BETTER DECISION INTELLIGENCE → BETTER OPERATING DECISIONS → LOWER RESOURCE WASTE → GUEST EXPERIENCE PROTECTED → MEASURABLE BUSINESS VALUE
A20: B · EXECUTIVE SCORECARD
A21: ="Period: governance review week "&$B$4&" (cell B4). Weekly metrics read that week; pilot-level and financial metrics are fixed pilot results. Status and Required Action calculate automatically." -> Period: governance review week A6 (cell B4). Weekly metrics read that week; pilot-level and financial metrics are fixed pilot results. Status and Required Action calculate automatically. | N21: CALCULATION HELPERS · blue = editable
A22: Strategic Objective | B22: KPI | C22: Baseline | D22: Current | E22: Target | F22: Variance | G22: Trend | H22: Status | I22: Owner | J22: Review Cadence | K22: Strategic Initiative | L22: Required Action | N22: Direction | O22: Tolerance | P22: Data Source | Q22: Action if not on track | R22: Display format
A23: Improve Decision Intelligence | B23: Forecast MAPE | C23: ='Forecast MAPE'!F2 -> 0.17775 | D23: =INDEX('Forecast MAPE'!$C$2:$C$13,MATCH($B$4,'Forecast MAPE'!$A$2:$A$13,0)) -> 0.085 | E23: ='Readiness Gate'!C7 -> 0.1 | F23: =IF(OR(D23="",E23=""),"—",D23-E23) -> -0.015 | G23: =IF(OR(C23="",D23=""),"—",IF(D23=C23,"► Flat",IF((N23="Higher")=(D23>C23),"▲ Improving","▼ Worsening"))) -> ▲ Improving | H23: =IF(D23="","—",IF(N23="Higher",IF(D23>=E23,"ON TRACK",IF(D23>=E23-O23,"AT RISK","OFF TRACK")),IF(D23<=E23,"ON TRACK",IF(D23<=E23+O23,"AT RISK","OFF TRACK")))) -> ON TRACK | I23: AI / Product | J23: Weekly | K23: Improve demand forecasting | L23: =IF(H23="ON TRACK","Continue — review "&LOWER(J23),IF(A23="Earn Greater AI Autonomy","Hold Autonomy — "&Q23,IF(A23="Create Sustainable Business Value","Adjust Initiative — "&Q23,IF(H23="AT RISK","Investigate — "&Q23,"Escalate — "&Q23)))) -> Continue — review weekly | N23: Lower | O23: 0 | P23: Forecast MAPE | Q23: retrain the demand model on chef-adjusted actuals | R23: 0.0%
A24: Improve Decision Intelligence | B24: Recommendation Acceptance | C24: =AgentOps!J2 -> 0.61 | D24: =INDEX(AgentOps!$J$2:$J$9,MATCH($B$4,AgentOps!$A$2:$A$9,0)) -> 0.83333333 | E24: ='Readiness Gate'!C2 -> 0.8 | F24: =IF(OR(D24="",E24=""),"—",D24-E24) -> 0.033333333 | G24: =IF(OR(C24="",D24=""),"—",IF(D24=C24,"► Flat",IF((N24="Higher")=(D24>C24),"▲ Improving","▼ Worsening"))) -> ▲ Improving | H24: =IF(D24="","—",IF(N24="Higher",IF(D24>=E24,"ON TRACK",IF(D24>=E24-O24,"AT RISK","OFF TRACK")),IF(D24<=E24,"ON TRACK",IF(D24<=E24+O24,"AT RISK","OFF TRACK")))) -> ON TRACK | I24: Operations | J24: Weekly | K24: Introduce governed production recommendations | L24: =IF(H24="ON TRACK","Continue — review "&LOWER(J24),IF(A24="Earn Greater AI Autonomy","Hold Autonomy — "&Q24,IF(A24="Create Sustainable Business Value","Adjust Initiative — "&Q24,IF(H24="AT RISK","Investigate — "&Q24,"Escalate — "&Q24)))) -> Continue — review weekly | N24: Higher | O24: 0 | P24: AgentOps | Q24: review rejected recommendations with chefs | R24: 0.0%
A25: Improve Decision Intelligence | B25: Context Completeness (A8, modeled) | D25: ='Control Room'!C10 -> 0.978 | E25: 0.95 | F25: =IF(OR(D25="",E25=""),"—",D25-E25) -> 0.028 | G25: =IF(OR(C25="",D25=""),"—",IF(D25=C25,"► Flat",IF((N25="Higher")=(D25>C25),"▲ Improving","▼ Worsening"))) -> — | H25: =IF(D25="","—",IF(N25="Higher",IF(D25>=E25,"ON TRACK",IF(D25>=E25-O25,"AT RISK","OFF TRACK")),IF(D25<=E25,"ON TRACK",IF(D25<=E25+O25,"AT RISK","OFF TRACK")))) -> ON TRACK | I25: IT / Data | J25: Daily | K25: Connect inventory context | L25: =IF(H25="ON TRACK","Continue — review "&LOWER(J25),IF(A25="Earn Greater AI Autonomy","Hold Autonomy — "&Q25,IF(A25="Create Sustainable Business Value","Adjust Initiative — "&Q25,IF(H25="AT RISK","Investigate — "&Q25,"Escalate — "&Q25)))) -> Continue — review daily | N25: Higher | O25: 0 | P25: Control Room (modeled) | Q25: restore missing data feeds before execution | R25: 0.0%
A26: Improve Operational Efficiency | B26: Weekly Food Waste (kg) | C26: ='Weekly Waste'!F2 -> 488.5 | D26: =INDEX('Weekly Waste'!$C$2:$C$13,MATCH($B$4,'Weekly Waste'!$A$2:$A$13,0)) -> 310 | E26: =ROUND(C26*(1+$E$47),0) -> 342 | F26: =IF(OR(D26="",E26=""),"—",D26-E26) -> -32 | G26: =IF(OR(C26="",D26=""),"—",IF(D26=C26,"► Flat",IF((N26="Higher")=(D26>C26),"▲ Improving","▼ Worsening"))) -> ▲ Improving | H26: =IF(D26="","—",IF(N26="Higher",IF(D26>=E26,"ON TRACK",IF(D26>=E26-O26,"AT RISK","OFF TRACK")),IF(D26<=E26,"ON TRACK",IF(D26<=E26+O26,"AT RISK","OFF TRACK")))) -> ON TRACK | I26: F&B Leadership | J26: Weekly | K26: Monitor waste root causes | L26: =IF(H26="ON TRACK","Continue — review "&LOWER(J26),IF(A26="Earn Greater AI Autonomy","Hold Autonomy — "&Q26,IF(A26="Create Sustainable Business Value","Adjust Initiative — "&Q26,IF(H26="AT RISK","Investigate — "&Q26,"Escalate — "&Q26)))) -> Continue — review weekly | N26: Lower | O26: 25 | P26: Weekly Waste | Q26: run a root-cause review on the top waste category | R26: #,##0
A27: Improve Operational Efficiency | B27: Overproduction (kg / week, final 4-wk avg) | C27: ='Waste by Source'!B2 -> 215 | D27: ='Waste by Source'!C2 -> 103 | E27: 120 | F27: =IF(OR(D27="",E27=""),"—",D27-E27) -> -17 | G27: =IF(OR(C27="",D27=""),"—",IF(D27=C27,"► Flat",IF((N27="Higher")=(D27>C27),"▲ Improving","▼ Worsening"))) -> ▲ Improving | H27: =IF(D27="","—",IF(N27="Higher",IF(D27>=E27,"ON TRACK",IF(D27>=E27-O27,"AT RISK","OFF TRACK")),IF(D27<=E27,"ON TRACK",IF(D27<=E27+O27,"AT RISK","OFF TRACK")))) -> ON TRACK | I27: Operations | J27: Weekly | K27: Introduce governed production recommendations | L27: =IF(H27="ON TRACK","Continue — review "&LOWER(J27),IF(A27="Earn Greater AI Autonomy","Hold Autonomy — "&Q27,IF(A27="Create Sustainable Business Value","Adjust Initiative — "&Q27,IF(H27="AT RISK","Investigate — "&Q27,"Escalate — "&Q27)))) -> Continue — review weekly | N27: Lower | O27: 10 | P27: Waste by Source | Q27: tighten prep ranges on chronic items | R27: #,##0
A28: Improve Operational Efficiency | B28: Waste per Cover (kg) | C28: ='Guest Experience'!D15 -> 0.16375 | D28: =INDEX('Guest Experience'!$C$2:$C$13,MATCH($B$4,'Guest Experience'!$A$2:$A$13,0)) -> 0.104 | E28: 0.115 | F28: =IF(OR(D28="",E28=""),"—",D28-E28) -> -0.011 | G28: =IF(OR(C28="",D28=""),"—",IF(D28=C28,"► Flat",IF((N28="Higher")=(D28>C28),"▲ Improving","▼ Worsening"))) -> ▲ Improving | H28: =IF(D28="","—",IF(N28="Higher",IF(D28>=E28,"ON TRACK",IF(D28>=E28-O28,"AT RISK","OFF TRACK")),IF(D28<=E28,"ON TRACK",IF(D28<=E28+O28,"AT RISK","OFF TRACK")))) -> ON TRACK | I28: F&B Leadership | J28: Weekly | K28: Monitor waste root causes | L28: =IF(H28="ON TRACK","Continue — review "&LOWER(J28),IF(A28="Earn Greater AI Autonomy","Hold Autonomy — "&Q28,IF(A28="Create Sustainable Business Value","Adjust Initiative — "&Q28,IF(H28="AT RISK","Investigate — "&Q28,"Escalate — "&Q28)))) -> Continue — review weekly | N28: Lower | O28: 0.01 | P28: Guest Experience | Q28: review portioning and buffet refill rules | R28: 0.000
A29: Improve Operational Efficiency | B29: Manager Hours Saved / Week | C29: 0 | D29: =Operations!$B$2-INDEX(Operations!$B$2:$B$10,MATCH($B$4,Operations!$A$2:$A$10,0)) -> 7.1 | E29: 8 | F29: =IF(OR(D29="",E29=""),"—",D29-E29) -> -0.9 | G29: =IF(OR(C29="",D29=""),"—",IF(D29=C29,"► Flat",IF((N29="Higher")=(D29>C29),"▲ Improving","▼ Worsening"))) -> ▲ Improving | H29: =IF(D29="","—",IF(N29="Higher",IF(D29>=E29,"ON TRACK",IF(D29>=E29-O29,"AT RISK","OFF TRACK")),IF(D29<=E29,"ON TRACK",IF(D29<=E29+O29,"AT RISK","OFF TRACK")))) -> AT RISK | I29: Operations | J29: Monthly | K29: Introduce governed production recommendations | L29: =IF(H29="ON TRACK","Continue — review "&LOWER(J29),IF(A29="Earn Greater AI Autonomy","Hold Autonomy — "&Q29,IF(A29="Create Sustainable Business Value","Adjust Initiative — "&Q29,IF(H29="AT RISK","Investigate — "&Q29,"Escalate — "&Q29)))) -> Investigate — remove manual re-work from the approval flow | N29: Higher | O29: 1.5 | P29: Operations | Q29: remove manual re-work from the approval flow | R29: 0.0
A30: Protect Guest Value | B30: Guest F&B Score | C30: ='Guest Experience'!D2 -> 4.61 | D30: =INDEX('Guest Experience'!$D$2:$D$13,MATCH($B$4,'Guest Experience'!$A$2:$A$13,0)) -> 4.65 | E30: ='Readiness Gate'!C8 -> 4.6 | F30: =IF(OR(D30="",E30=""),"—",D30-E30) -> 0.05 | G30: =IF(OR(C30="",D30=""),"—",IF(D30=C30,"► Flat",IF((N30="Higher")=(D30>C30),"▲ Improving","▼ Worsening"))) -> ▲ Improving | H30: =IF(D30="","—",IF(N30="Higher",IF(D30>=E30,"ON TRACK",IF(D30>=E30-O30,"AT RISK","OFF TRACK")),IF(D30<=E30,"ON TRACK",IF(D30<=E30+O30,"AT RISK","OFF TRACK")))) -> ON TRACK | I30: F&B Leadership | J30: Weekly | K30: Operate readiness gate | L30: =IF(H30="ON TRACK","Continue — review "&LOWER(J30),IF(A30="Earn Greater AI Autonomy","Hold Autonomy — "&Q30,IF(A30="Create Sustainable Business Value","Adjust Initiative — "&Q30,IF(H30="AT RISK","Investigate — "&Q30,"Escalate — "&Q30)))) -> Continue — review weekly | N30: Higher | O30: 0 | P30: Guest Experience | Q30: pause reductions on affected menu items | R30: 0.00
A31: Protect Guest Value | B31: Guest Experience Guardrail (% of agent weeks ≥ score floor) | D31: =SUMPRODUCT(('Guest Experience'!$D$6:$D$13>=$E$30)*(ROW('Guest Experience'!$D$6:$D$13)-5<=MATCH($B$4,'Guest Experience'!$A$6:$A$13,0)))/MATCH($B$4,'Guest Experience'!$A$6:$A$13,0) -> 1 | E31: 1 | F31: =IF(OR(D31="",E31=""),"—",D31-E31) -> 0 | G31: =IF(OR(C31="",D31=""),"—",IF(D31=C31,"► Flat",IF((N31="Higher")=(D31>C31),"▲ Improving","▼ Worsening"))) -> — | H31: =IF(D31="","—",IF(N31="Higher",IF(D31>=E31,"ON TRACK",IF(D31>=E31-O31,"AT RISK","OFF TRACK")),IF(D31<=E31,"ON TRACK",IF(D31<=E31+O31,"AT RISK","OFF TRACK")))) -> ON TRACK | I31: Risk / Governance | J31: Weekly | K31: Operate readiness gate | L31: =IF(H31="ON TRACK","Continue — review "&LOWER(J31),IF(A31="Earn Greater AI Autonomy","Hold Autonomy — "&Q31,IF(A31="Create Sustainable Business Value","Adjust Initiative — "&Q31,IF(H31="AT RISK","Investigate — "&Q31,"Escalate — "&Q31)))) -> Continue — review weekly | N31: Higher | O31: 0 | P31: Guest Experience | Q31: reduce autonomy and investigate guest impact | R31: 0%
A32: Protect Guest Value | B32: Service-Related Exceptions / Week (modeled) | C32: 5 | D32: 2 | E32: 3 | F32: =IF(OR(D32="",E32=""),"—",D32-E32) -> -1 | G32: =IF(OR(C32="",D32=""),"—",IF(D32=C32,"► Flat",IF((N32="Higher")=(D32>C32),"▲ Improving","▼ Worsening"))) -> ▲ Improving | H32: =IF(D32="","—",IF(N32="Higher",IF(D32>=E32,"ON TRACK",IF(D32>=E32-O32,"AT RISK","OFF TRACK")),IF(D32<=E32,"ON TRACK",IF(D32<=E32+O32,"AT RISK","OFF TRACK")))) -> ON TRACK | I32: Operations | J32: Weekly | K32: Connect inventory context | L32: =IF(H32="ON TRACK","Continue — review "&LOWER(J32),IF(A32="Earn Greater AI Autonomy","Hold Autonomy — "&Q32,IF(A32="Create Sustainable Business Value","Adjust Initiative — "&Q32,IF(H32="AT RISK","Investigate — "&Q32,"Escalate — "&Q32)))) -> Continue — review weekly | N32: Lower | O32: 1 | P32: Modeled input (illustrative) | Q32: review stockouts against production cuts | R32: 0
A33: Create Sustainable Business Value | B33: Food Cost Avoided (annual) | D33: ='Waste Cost'!B9 -> 145000 | E33: 100000 | F33: =IF(OR(D33="",E33=""),"—",D33-E33) -> 45000 | G33: =IF(OR(C33="",D33=""),"—",IF(D33=C33,"► Flat",IF((N33="Higher")=(D33>C33),"▲ Improving","▼ Worsening"))) -> — | H33: =IF(D33="","—",IF(N33="Higher",IF(D33>=E33,"ON TRACK",IF(D33>=E33-O33,"AT RISK","OFF TRACK")),IF(D33<=E33,"ON TRACK",IF(D33<=E33+O33,"AT RISK","OFF TRACK")))) -> ON TRACK | I33: F&B Leadership | J33: Quarterly | K33: Agent-enabled demand and production decision system | L33: =IF(H33="ON TRACK","Continue — review "&LOWER(J33),IF(A33="Earn Greater AI Autonomy","Hold Autonomy — "&Q33,IF(A33="Create Sustainable Business Value","Adjust Initiative — "&Q33,IF(H33="AT RISK","Investigate — "&Q33,"Escalate — "&Q33)))) -> Continue — review quarterly | N33: Higher | O33: 20000 | P33: Waste Cost | Q33: re-baseline purchasing assumptions | R33: $#,##0
A34: Create Sustainable Business Value | B34: Net Annual Benefit (after AI cost) | D34: =Economics!B24 -> 135508 | E34: =Sensitivity!C12 -> 74989.2 | F34: =IF(OR(D34="",E34=""),"—",D34-E34) -> 60518.8 | G34: =IF(OR(C34="",D34=""),"—",IF(D34=C34,"► Flat",IF((N34="Higher")=(D34>C34),"▲ Improving","▼ Worsening"))) -> — | H34: =IF(D34="","—",IF(N34="Higher",IF(D34>=E34,"ON TRACK",IF(D34>=E34-O34,"AT RISK","OFF TRACK")),IF(D34<=E34,"ON TRACK",IF(D34<=E34+O34,"AT RISK","OFF TRACK")))) -> ON TRACK | I34: F&B Leadership | J34: Quarterly | K34: Agent-enabled demand and production decision system | L34: =IF(H34="ON TRACK","Continue — review "&LOWER(J34),IF(A34="Earn Greater AI Autonomy","Hold Autonomy — "&Q34,IF(A34="Create Sustainable Business Value","Adjust Initiative — "&Q34,IF(H34="AT RISK","Investigate — "&Q34,"Escalate — "&Q34)))) -> Continue — review quarterly | N34: Higher | O34: 15000 | P34: Economics · Sensitivity | Q34: revisit AI operating-cost assumptions | R34: $#,##0
A35: Create Sustainable Business Value | B35: Year-1 ROI | D35: =Economics!B26 -> 1.0867819 | E35: 0.5 | F35: =IF(OR(D35="",E35=""),"—",D35-E35) -> 0.5867819 | G35: =IF(OR(C35="",D35=""),"—",IF(D35=C35,"► Flat",IF((N35="Higher")=(D35>C35),"▲ Improving","▼ Worsening"))) -> — | H35: =IF(D35="","—",IF(N35="Higher",IF(D35>=E35,"ON TRACK",IF(D35>=E35-O35,"AT RISK","OFF TRACK")),IF(D35<=E35,"ON TRACK",IF(D35<=E35+O35,"AT RISK","OFF TRACK")))) -> ON TRACK | I35: F&B Leadership | J35: Quarterly | K35: Agent-enabled demand and production decision system | L35: =IF(H35="ON TRACK","Continue — review "&LOWER(J35),IF(A35="Earn Greater AI Autonomy","Hold Autonomy — "&Q35,IF(A35="Create Sustainable Business Value","Adjust Initiative — "&Q35,IF(H35="AT RISK","Investigate — "&Q35,"Escalate — "&Q35)))) -> Continue — review quarterly | N35: Higher | O35: 0.25 | P35: Economics | Q35: phase integration spend | R35: 0%
A36: Create Sustainable Business Value | B36: Payback (months) | D36: =Economics!B27 -> 4.4277829 | E36: 12 | F36: =IF(OR(D36="",E36=""),"—",D36-E36) -> -7.5722171 | G36: =IF(OR(C36="",D36=""),"—",IF(D36=C36,"► Flat",IF((N36="Higher")=(D36>C36),"▲ Improving","▼ Worsening"))) -> — | H36: =IF(D36="","—",IF(N36="Higher",IF(D36>=E36,"ON TRACK",IF(D36>=E36-O36,"AT RISK","OFF TRACK")),IF(D36<=E36,"ON TRACK",IF(D36<=E36+O36,"AT RISK","OFF TRACK")))) -> ON TRACK | I36: F&B Leadership | J36: Quarterly | K36: Agent-enabled demand and production decision system | L36: =IF(H36="ON TRACK","Continue — review "&LOWER(J36),IF(A36="Earn Greater AI Autonomy","Hold Autonomy — "&Q36,IF(A36="Create Sustainable Business Value","Adjust Initiative — "&Q36,IF(H36="AT RISK","Investigate — "&Q36,"Escalate — "&Q36)))) -> Continue — review quarterly | N36: Lower | O36: 6 | P36: Economics | Q36: phase integration spend | R36: 0.0
A37: Earn Greater AI Autonomy | B37: Tool / System Reliability | C37: =AgentOps!N2 -> 0.96730769 | D37: =INDEX(AgentOps!$N$2:$N$9,MATCH($B$4,AgentOps!$A$2:$A$9,0)) -> 0.9890625 | E37: ='Readiness Gate'!C5 -> 0.99 | F37: =IF(OR(D37="",E37=""),"—",D37-E37) -> -0.0009375 | G37: =IF(OR(C37="",D37=""),"—",IF(D37=C37,"► Flat",IF((N37="Higher")=(D37>C37),"▲ Improving","▼ Worsening"))) -> ▲ Improving | H37: =IF(D37="","—",IF(N37="Higher",IF(D37>=E37,"ON TRACK",IF(D37>=E37-O37,"AT RISK","OFF TRACK")),IF(D37<=E37,"ON TRACK",IF(D37<=E37+O37,"AT RISK","OFF TRACK")))) -> OFF TRACK | I37: IT / Data | J37: Weekly | K37: Operate readiness gate | L37: =IF(H37="ON TRACK","Continue — review "&LOWER(J37),IF(A37="Earn Greater AI Autonomy","Hold Autonomy — "&Q37,IF(A37="Create Sustainable Business Value","Adjust Initiative — "&Q37,IF(H37="AT RISK","Investigate — "&Q37,"Escalate — "&Q37)))) -> Hold Autonomy — fix failing integrations before any authority review | N37: Higher | O37: 0 | P37: AgentOps · Readiness Gate | Q37: fix failing integrations before any authority review | R37: 0.0%
A38: Earn Greater AI Autonomy | B38: Escalation Recall | C38: =AgentOps!L2 -> 0.74074074 | D38: =INDEX(AgentOps!$L$2:$L$9,MATCH($B$4,AgentOps!$A$2:$A$9,0)) -> 0.92 | E38: ='Readiness Gate'!C3 -> 0.9 | F38: =IF(OR(D38="",E38=""),"—",D38-E38) -> 0.02 | G38: =IF(OR(C38="",D38=""),"—",IF(D38=C38,"► Flat",IF((N38="Higher")=(D38>C38),"▲ Improving","▼ Worsening"))) -> ▲ Improving | H38: =IF(D38="","—",IF(N38="Higher",IF(D38>=E38,"ON TRACK",IF(D38>=E38-O38,"AT RISK","OFF TRACK")),IF(D38<=E38,"ON TRACK",IF(D38<=E38+O38,"AT RISK","OFF TRACK")))) -> ON TRACK | I38: Risk / Governance | J38: Weekly | K38: Review human overrides | L38: =IF(H38="ON TRACK","Continue — review "&LOWER(J38),IF(A38="Earn Greater AI Autonomy","Hold Autonomy — "&Q38,IF(A38="Create Sustainable Business Value","Adjust Initiative — "&Q38,IF(H38="AT RISK","Investigate — "&Q38,"Escalate — "&Q38)))) -> Continue — review weekly | N38: Higher | O38: 0 | P38: AgentOps | Q38: audit missed escalations | R38: 0.0%
A39: Earn Greater AI Autonomy | B39: Human Override Rate | C39: =AgentOps!K2 -> 0.29 | D39: =INDEX(AgentOps!$K$2:$K$9,MATCH($B$4,AgentOps!$A$2:$A$9,0)) -> 0.12878788 | E39: ='Readiness Gate'!C6 -> 0.15 | F39: =IF(OR(D39="",E39=""),"—",D39-E39) -> -0.021212121 | G39: =IF(OR(C39="",D39=""),"—",IF(D39=C39,"► Flat",IF((N39="Higher")=(D39>C39),"▲ Improving","▼ Worsening"))) -> ▲ Improving | H39: =IF(D39="","—",IF(N39="Higher",IF(D39>=E39,"ON TRACK",IF(D39>=E39-O39,"AT RISK","OFF TRACK")),IF(D39<=E39,"ON TRACK",IF(D39<=E39+O39,"AT RISK","OFF TRACK")))) -> ON TRACK | I39: AI / Product | J39: Weekly | K39: Review human overrides | L39: =IF(H39="ON TRACK","Continue — review "&LOWER(J39),IF(A39="Earn Greater AI Autonomy","Hold Autonomy — "&Q39,IF(A39="Create Sustainable Business Value","Adjust Initiative — "&Q39,IF(H39="AT RISK","Investigate — "&Q39,"Escalate — "&Q39)))) -> Continue — review weekly | N39: Lower | O39: 0 | P39: AgentOps · Overrides | Q39: diagnose override reasons and retrain | R39: 0.0%
A40: Earn Greater AI Autonomy | B40: Production Readiness Gate (all 8 criteria) | C40: ='Readiness Gate'!K12 -> HOLD | D40: =INDEX('Readiness Gate'!$K$12:$K$19,MATCH($B$4,'Readiness Gate'!$A$12:$A$19,0)) -> HOLD | E40: PASS | F40: — | G40: =IF(D40=C40,"► Flat",IF(D40="PASS","▲ Improving","▼ Worsening")) -> ► Flat | H40: =IF(D40="PASS","ON TRACK","OFF TRACK") -> OFF TRACK | I40: Risk / Governance | J40: Weekly | K40: Operate readiness gate | L40: =IF(D40="PASS","Scale — convene a decision-authority review","Hold Autonomy — resolve first blocker: "&INDEX('Readiness Gate'!$L$12:$L$19,MATCH($B$4,'Readiness Gate'!$A$12:$A$19,0))) -> Hold Autonomy — resolve first blocker: Tool reliability | N40: Gate | O40: — | P40: Readiness Gate | Q40: resolve the first blocker | R40: @
A41: Status: ON TRACK = meets target · AT RISK = misses target but within tolerance (col O) · OFF TRACK = outside tolerance. Readiness-gate criteria use zero tolerance. Trend compares Current with Baseline (baseline for agent-only metrics = week A1). Blue = editable illustrative targets and tolerances; green = linked from other sheets; black = calculated.
A43: C · PERDOO-STYLE STRATEGY / OKR VIEW
...
